Workbook

Sheet TD
C2: Tasas de Falla Promedio Anuales
C3: Año | D3: E | E3: FM | F3: I
C4: 2018 | D4: 0.0053619303 | E4: 0.058981233 | F4: 0.93565684
C5: 2019 | D5: 0.034602076 | E5: 0.16608997 | F5: 0.79930796
C6: 2020 | D6: 0.073800738 | E6: 0.17343173 | F6: 0.75276753
C7: 2021 | D7: 0.055555556 | E7: 0.11111111 | F7: 0.83333333
C8: 2022 | D8: 0.062695925 | E8: 0.1661442 | F8: 0.77115987
C10: Tipos de Fallas
C11: E | E11: FM | G11: I | I11: Total Fallas | J11: Total Promedio de Horas
B12: Año | C12: Fallas | D12: Promedio de Horas | E12: Fallas | F12: Promedio de Horas | G12: Fallas | H12: Promedio de Horas
B13: 2018 | C13: 2 | D13: 1.3927778 | E13: 22 | F13: 3.0809848 | G13: 349 | H13: 2.3310928 | I13: 373 | J13: 2.3702912
B14: 2019 | C14: 10 | D14: 0.889 | E14: 48 | F14: 2.6275 | G14: 231 | H14: 2.3590476 | I14: 289 | J14: 2.3527682
B15: 2020 | C15: 20 | D15: 0.764 | E15: 47 | F15: 2.4912766 | G15: 204 | H15: 2.1182353 | I15: 271 | J15: 2.0829889
B16: 2021 | C16: 13 | D16: 0.56692308 | E16: 26 | F16: 3.3019231 | G16: 195 | H16: 2.118359 | I16: 234 | J16: 2.1636752
B17: 2022 | C17: 20 | D17: 0.079 | E17: 53 | F17: 3.0830189 | G17: 246 | H17: 1.9105285 | I17: 319 | J17: 1.9905016
B18: 2023 | C18: 31 | D18: 0.23870968 | E18: 88 | F18: 38.132727 | G18: 164 | H18: 1.8744512 | I18: 283 | J18: 12.969929
B19: 2024 | C19: 44 | D19: 0.63022727 | E19: 69 | F19: 4.5528986 | G19: 151 | H19: 2.5869536 | I19: 264 | J19: 2.7746591
B20: 2025 | C20: 46 | D20: 2.3445652 | E20: 62 | F20: 2.515 | G20: 81 | H20: 2.1812346 | I20: 189 | J20: 2.3304762
B21: Total general | C21: 186 | D21: 0.9617503 | E21: 415 | F21: 10.568679 | G21: 1621 | H21: 2.18902 | I21: 2222 | J21: 3.651345
E23: =COUNTIF(Tabla1[Calificación], "=FM") -> 415
C26: Alimentador
C27: 2 | D27: Morza
C28: 6 | D28: Zapallar
C29: 7 | D29: Los Niches
C30: 8 | D30: Industrial
C31: 9 | D31: Los Queñes
C32: 10 | D32: La Laguna
C33: 11 | D33: La Obra

Sheet matriz de diagnostico
A3: Cuenta de INC | B3: Etiquetas de columna
A4: Etiquetas de fila | B4: 2018 | C4: 2019 | D4: 2020 | E4: 2021 | F4: 2022 | G4: 2023 | H4: 2024 | I4: 2025 | J4: Total general
A5: 1 | B5: 1 | C5: 9 | D5: 2 | F5: 9 | G5: 3 | H5: 4 | J5: 28
A6: 2 | D6: 13 | G6: 1 | J6: 14
A7: 3 | C7: 5 | D7: 5 | F7: 6 | G7: 5 | J7: 21
A8: 4 | B8: 2 | C8: 7 | D8: 16 | E8: 22 | F8: 22 | G8: 20 | H8: 52 | I8: 9 | J8: 150
A9: 5 | B9: 5 | C9: 40 | D9: 46 | E9: 43 | F9: 55 | G9: 46 | H9: 48 | I9: 22 | J9: 305
A10: 6 | G10: 15 | J10: 15
A11: 8 | C11: 4 | D11: 2 | E11: 8 | F11: 8 | G11: 8 | H11: 13 | I11: 7 | J11: 50
A12: 9 | D12: 1 | E12: 1 | G12: 2 | J12: 4
A13: 10 | C13: 1 | D13: 2 | F13: 1 | H13: 2 | J13: 6
A14: 11 | C14: 8 | D14: 7 | E14: 1 | F14: 7 | G14: 6 | H14: 8 | I14: 3 | J14: 40
A15: 12 | G15: 30 | J15: 30
A16: 13 | C16: 7 | D16: 5 | E16: 8 | F16: 7 | H16: 4 | J16: 31
A17: 15 | C17: 3 | J17: 3
A18: 16 | B18: 1 | I18: 5 | J18: 6
A19: 17 | C19: 2 | D19: 3 | E19: 5 | F19: 3 | G19: 3 | H19: 2 | I19: 1 | J19: 19
A20: 18 | C20: 5 | D20: 3 | F20: 1 | G20: 1 | I20: 9 | J20: 19
A21: 19 | C21: 10 | D21: 1 | G21: 2 | J21: 13
A22: 20 | B22: 4 | C22: 33 | D22: 32 | E22: 25 | F22: 45 | G22: 35 | H22: 37 | I22: 43 | J22: 254
A23: 21 | B23: 1 | C23: 1 | D23: 6 | E23: 1 | F23: 3 | G23: 4 | I23: 1 | J23: 17
A24: 22 | D24: 2 | E24: 1 | G24: 1 | J24: 4
A25: 23 | B25: 5 | C25: 31 | D25: 20 | E25: 25 | F25: 3 | G25: 1 | J25: 85
A26: 24 | F26: 8 | G26: 3 | H26: 1 | J26: 12
A27: 25 | C27: 18 | D27: 12 | E27: 8 | F27: 12 | G27: 3 | H27: 3 | I27: 8 | J27: 64
A28: 26 | B28: 5 | C28: 38 | D28: 24 | E28: 38 | F28: 39 | G28: 42 | H28: 20 | I28: 14 | J28: 220
A29: 28 | C29: 4 | E29: 3 | F29: 14 | G29: 2 | H29: 2 | J29: 25
A30: 29 | B30: 2 | C30: 16 | E30: 1 | F30: 3 | G30: 1 | I30: 1 | J30: 24
A31: 30 | B31: 1 | C31: 27 | D31: 47 | E31: 23 | F31: 52 | G31: 17 | H31: 23 | I31: 19 | J31: 209
A32: 31 | B32: 1 | C32: 7 | D32: 2 | E32: 8 | F32: 1 | G32: 1 | H32: 1 | I32: 1 | J32: 22
A33: 32 | C33: 9 | D33: 14 | E33: 12 | F33: 20 | G33: 22 | H33: 37 | I33: 46 | J33: 160
A34: 33 | B34: 2 | C34: 4 | D34: 6 | E34: 1 | G34: 9 | H34: 7 | J34: 29
A35: 1101 | B35: 23 | J35: 23
A36: 1105 | B36: 4 | J36: 4
A37: 1106 | B37: 4 | J37: 4
A38: 1402 | B38: 5 | J38: 5
A39: 1501 | B39: 1 | J39: 1
A40: 1502 | B40: 2 | J40: 2
A41: 1601 | B41: 12 | J41: 12
A42: 1602 | B42: 3 | J42: 3
...

Sheet faltas de coordenadas
A3: Etiquetas de fila | B3: Promedio de Falta_coordenada
A4: 2 | B4: 0.43287671
A5: 6 | B5: 0.22159091
A6: 7 | B6: 0.29847909
A7: 8 | B7: 0.45810056
A8: 9 | B8: 0.21875
A9: 10 | B9: 0.52469136
A10: 11 | B10: 1
A11: Total general | B11: 0.33123312

Sheet BD
B2: INC | C2: Alimentador | D2: Trafos afectados | E2: KVA | F2: Clientes | G2: Inicio | H2: Fin | I2: Duracion | J2: Causa | K2: Calificación | L2: Comuna id | M2: Comuna | N2: Tension | O2: X | P2: Y | Q2: Descripcion | R2: Validacion_Taxonomia | S2: año | T2: Falta_coordenada
B3: 201800001 | C3: 9 | D3: 1 | E3: 15 | F3: 9 | G3: 43105.749 | H3: 43105.938 | I3: 4.5333333 | J3: 1801 | K3: I | L3: 7308 | M3: Teno | N3: MT | O3: 315569.53 | P3: 6136152.3 | Q3: Se abre DTE5542 | R3: =IF(ISNUMBER(MATCH(J3, Causas!B:B, 0)), "Taxonomía Nueva", IF(ISNUMBER(MATCH(J3, 'Causas 1'!B:B, 0)), "Taxonomía Antigua", "HUÉRFANO")) -> Taxonomía Antigua | S3: =YEAR(G3) -> 2018 | T3: =IF(OR(ISBLANK(O2), O2=0, O2="", ISBLANK(P2), P2=0, P2=""), 1, 0) -> 0
B4: 201800002 | C4: 8 | D4: 2 | E4: 33 | F4: 3 | G4: 43106.813 | H4: 43106.861 | I4: 1.15 | J4: 1802 | K4: I | L4: 7301 | M4: Curicó | N4: MT | O4: 302667.64 | P4: 6126660.1 | Q4: Se abre DCU3836 | R4: =IF(ISNUMBER(MATCH(J4, Causas!B:B, 0)), "Taxonomía Nueva", IF(ISNUMBER(MATCH(J4, 'Causas 1'!B:B, 0)), "Taxonomía Antigua", "HUÉRFANO")) -> Taxonomía Antigua | S4: =YEAR(G4) -> 2018 | T4: =IF(OR(ISBLANK(O3), O3=0, O3="", ISBLANK(P3), P3=0, P3=""), 1, 0) -> 0
B5: 201800003 | C5: 6 | D5: 3 | E5: 45 | F5: 58 | G5: 43109.599 | H5: 43109.682 | I5: 2 | J5: 2701 | K5: I | L5: 7301 | M5: Curicó | N5: MT | O5: 301623.15 | P5: 6119323.9 | Q5: Se abre DCU5308 | R5: =IF(ISNUMBER(MATCH(J5, Causas!B:B, 0)), "Taxonomía Nueva", IF(ISNUMBER(MATCH(J5, 'Causas 1'!B:B, 0)), "Taxonomía Antigua", "HUÉRFANO")) -> Taxonomía Antigua | S5: =YEAR(G5) -> 2018 | T5: =IF(OR(ISBLANK(O4), O4=0, O4="", ISBLANK(P4), P4=0, P4=""), 1, 0) -> 0
B6: 201800004 | C6: 2 | D6: 4 | E6: 845 | F6: 4 | G6: 43110.43 | H6: 43110.49 | I6: 1.4333333 | J6: 2304 | K6: I | L6: 7308 | M6: Teno | N6: MT | O6: 315907.44 | P6: 6141073 | Q6: Se abre DTE5279 | R6: =IF(ISNUMBER(MATCH(J6, Causas!B:B, 0)), "Taxonomía Nueva", IF(ISNUMBER(MATCH(J6, 'Causas 1'!B:B, 0)), "Taxonomía Antigua", "HUÉRFANO")) -> Taxonomía Antigua | S6: =YEAR(G6) -> 2018 | T6: =IF(OR(ISBLANK(O5), O5=0, O5="", ISBLANK(P5), P5=0, P5=""), 1, 0) -> 0
B7: 201800005 | C7: 6 | D7: 3 | E7: 45 | F7: 58 | G7: 43110.49 | H7: 43110.562 | I7: 1.75 | J7: 2701 | K7: I | L7: 7301 | M7: Curicó | N7: MT | O7: 302172.31 | P7: 6119390.1 | Q7: Se abre DCU5308 | R7: =IF(ISNUMBER(MATCH(J7, Causas!B:B, 0)), "Taxonomía Nueva", IF(ISNUMBER(MATCH(J7, 'Causas 1'!B:B, 0)), "Taxonomía Antigua", "HUÉRFANO")) -> Taxonomía Antigua | S7: =YEAR(G7) -> 2018 | T7: =IF(OR(ISBLANK(O6), O6=0, O6="", ISBLANK(P6), P6=0, P6=""), 1, 0) -> 0
B8: 201800006 | C8: 9 | D8: 12 | E8: 233 | F8: 162 | G8: 43110.853 | H8: 43110.927 | I8: 1.7833333 | J8: 1601 | K8: FM | L8: 7308 | M8: Teno | N8: MT | O8: 315339.11 | P8: 6133419.6 | Q8: Se abre DTE4513 | R8: =IF(ISNUMBER(MATCH(J8, Causas!B:B, 0)), "Taxonomía Nueva", IF(ISNUMBER(MATCH(J8, 'Causas 1'!B:B, 0)), "Taxonomía Antigua", "HUÉRFANO")) -> Taxonomía Antigua | S8: =YEAR(G8) -> 2018 | T8: =IF(OR(ISBLANK(O7), O7=0, O7="", ISBLANK(P7), P7=0, P7=""), 1, 0) -> 0
B9: 201800007 | C9: 9 | D9: 18 | E9: 885 | F9: 259 | G9: 43112.047 | H9: 43112.108 | I9: 1.45 | J9: 2203 | K9: I | L9: 7308 | M9: Teno | N9: MT | O9: 309703.45 | P9: 6139415.3 | Q9: Se abre DTE2705 | R9: =IF(ISNUMBER(MATCH(J9, Causas!B:B, 0)), "Taxonomía Nueva", IF(ISNUMBER(MATCH(J9, 'Causas 1'!B:B, 0)), "Taxonomía Antigua", "HUÉRFANO")) -> Taxonomía Antigua | S9: =YEAR(G9) -> 2018 | T9: =IF(OR(ISBLANK(O8), O8=0, O8="", ISBLANK(P8), P8=0, P8=""), 1, 0) -> 0
B10: 201800008 | C10: 2 | D10: 2 | E10: 55 | F10: 2 | G10: 43112.681 | H10: 43112.761 | I10: 1.9333333 | J10: 1101 | K10: I | L10: 7308 | M10: Teno | N10: MT | O10: 312406.85 | P10: 6146516.5 | Q10: Se abre DTE3604 | R10: =IF(ISNUMBER(MATCH(J10, Causas!B:B, 0)), "Taxonomía Nueva", IF(ISNUMBER(MATCH(J10, 'Causas 1'!B:B, 0)), "Taxonomía Antigua", "HUÉRFANO")) -> Taxonomía Antigua | S10: =YEAR(G10) -> 2018 | T10: =IF(OR(ISBLANK(O9), O9=0, O9="", ISBLANK(P9), P9=0, P9=""), 1, 0) -> 0
B11: 201800009 | C11: 9 | D11: 3 | E11: 35 | F11: 5 | G11: 43113.81 | H11: 43113.854 | I11: 1.0666667 | J11: 2304 | K11: I | L11: 7306 | M11: Romeral | N11: MT | O11: 332076.59 | P11: 6124788.9 | Q11: Se abre DTE4889 | R11: =IF(ISNUMBER(MATCH(J11, Causas!B:B, 0)), "Taxonomía Nueva", IF(ISNUMBER(MATCH(J11, 'Causas 1'!B:B, 0)), "Taxonomía Antigua", "HUÉRFANO")) -> Taxonomía Antigua | S11: =YEAR(G11) -> 2018 | T11: =IF(OR(ISBLANK(O10), O10=0, O10="", ISBLANK(P10), P10=0, P10=""), 1, 0) -> 0
B12: 201800010 | C12: 7 | D12: 6 | E12: 245 | F12: 5 | G12: 43120.727 | H12: 43120.868 | I12: 3.3833333 | J12: 2401 | K12: I | L12: 7301 | M12: Curicó | N12: MT | O12: 313674.33 | P12: 6115521.8 | Q12: Se abre DCU2062 | R12: =IF(ISNUMBER(MATCH(J12, Causas!B:B, 0)), "Taxonomía Nueva", IF(ISNUMBER(MATCH(J12, 'Causas 1'!B:B, 0)), "Taxonomía Antigua", "HUÉRFANO")) -> Taxonomía Antigua | S12: =YEAR(G12) -> 2018 | T12: =IF(OR(ISBLANK(O11), O11=0, O11="", ISBLANK(P11), P11=0, P11=""), 1, 0) -> 0
B13: 201800011 | C13: 6 | D13: 1 | E13: 25 | F13: 47 | G13: 43121.89 | H13: 43121.938 | I13: 1.1333333 | J13: 1701 | K13: FM | L13: 7301 | M13: Curicó | N13: MT | O13: 298723.92 | P13: 6115497.1 | Q13: Se abre DCU3293 | R13: =IF(ISNUMBER(MATCH(J13, Causas!B:B, 0)), "Taxonomía Nueva", IF(ISNUMBER(MATCH(J13, 'Causas 1'!B:B, 0)), "Taxonomía Antigua", "HUÉRFANO")) -> Taxonomía Antigua | S13: =YEAR(G13) -> 2018 | T13: =IF(OR(ISBLANK(O12), O12=0, O12="", ISBLANK(P12), P12=0, P12=""), 1, 0) -> 0
B14: 201800012 | C14: 2 | D14: 5 | E14: 140 | F14: 41 | G14: 43124.785 | H14: 43124.865 | I14: 1.9166667 | J14: 1402 | K14: I | L14: 6303 | M14: Chimbarongo | N14: MT | O14: 311895.56 | P14: 6147369.9 | Q14: Se abre DTE4152 | R14: =IF(ISNUMBER(MATCH(J14, Causas!B:B, 0)), "Taxonomía Nueva", IF(ISNUMBER(MATCH(J14, 'Causas 1'!B:B, 0)), "Taxonomía Antigua", "HUÉRFANO")) -> Taxonomía Antigua | S14: =YEAR(G14) -> 2018 | T14: =IF(OR(ISBLANK(O13), O13=0, O13="", ISBLANK(P13), P13=0, P13=""), 1, 0) -> 0
... B596: 201901120 | C596: 9 | D596: 1 | E596: 5 | F596: 2 | G596: 43700.556 | H596: 43700.642 | I596: 2.08 | J596: 30 | K596: I | L596: 7308 | M596: Teno | N596: MT | O596: 320357.93 | P596: 6129411.8 | Q596: dte507 operado en mt fusible de 2st opera por fatiga de material dte507 operado en MT | R596: =IF(ISNUMBER(MATCH(J596, Causas!B:B, 0)), "Taxonomía Nueva", IF(ISNUMBER(MATCH(J596, 'Causas 1'!B:B, 0)), "Taxonomía Antigua", "HUÉRFANO")) -> Taxonomía Nueva | S596: =YEAR(G596) -> 2019 | T596: =IF(OR(ISBLANK(O595), O595=0, O595="", ISBLANK(P595), P595=0, P595=""), 1, 0) -> 0
B597: 201901125 | C597: 6 | D597: 162 | E597: 12948 | F597: 1470 | G597: 43702.42 | H597: 43702.663 | I597: 5.83 | J597: 25 | K597: I | L597: 7301 | M597: Curicó | N597: MT | O597: 2965450,43 | P597: 6125519,556 | Q597: DESCONEXION PROGRAMADA CAMBIO DE CONDUCTOR DESNUDO A PROTEGIDO. SE INSTALA GENERACION DE RESPALDO. | R597: =IF(ISNUMBER(MATCH(J597, Causas!B:B, 0)), "Taxonomía Nueva", IF(ISNUMBER(MATCH(J597, 'Causas 1'!B:B, 0)), "Taxonomía Antigua", "HUÉRFANO")) -> Taxonomía Nueva | S597: =YEAR(G597) -> 2019 | T597: =IF(OR(ISBLANK(O596), O596=0, O596="", ISBLANK(P596), P596=0, P596=""), 1, 0) -> 0
B598: 201901125 | C598: 6 | D598: 193 | E598: 18341.5 | F598: 2686 | G598: 43702.42 | H598: 43702.66 | I598: 5.75 | J598: 25 | K598: I | L598: 7301 | M598: Curicó | N598: MT | O598: 2965450,43 | P598: 6125519,556 | Q598: DESCONEXION PROGRAMADA CAMBIO DE CONDUCTOR DESNUDO A PROTEGIDO. SE INSTALA GENERACION DE RESPALDO. | R598: =IF(ISNUMBER(MATCH(J598, Causas!B:B, 0)), "Taxonomía Nueva", IF(ISNUMBER(MATCH(J598, 'Causas 1'!B:B, 0)), "Taxonomía Antigua", "HUÉRFANO")) -> Taxonomía Nueva | S598: =YEAR(G598) -> 2019 | T598: =IF(OR(ISBLANK(O597), O597=0, O597="", ISBLANK(P597), P597=0, P597=""), 1, 0) -> 0
B599: 201901136 | C599: 9 | D599: 10 | E599: 255 | F599: 113 | G599: 43706.418 | H599: 43706.646 | I599: 5.47 | J599: 25 | K599: I | L599: 7308 | M599: Teno | N599: MT | O599: 320325.24 | P599: 6129429.9 | Q599: DESCONEXION PROGRAMADA SECTOR LA ALAGUNA | R599: =IF(ISNUMBER(MATCH(J599, Causas!B:B, 0)), "Taxonomía Nueva", IF(ISNUMBER(MATCH(J599, 'Causas 1'!B:B, 0)), "Taxonomía Antigua", "HUÉRFANO")) -> Taxonomía Nueva | S599: =YEAR(G599) -> 2019 | T599: =IF(OR(ISBLANK(O598), O598=0, O598="", ISBLANK(P598), P598=0, P598=""), 1, 0) -> 0
B600: 201901144 | C600: 7 | D600: 0 | E600: 0 | F600: 20 | G600: 43709.599 | H600: 43709.685 | I600: 2.05 | J600: 30 | K600: I | L600: 7301 | M600: Curicó | N600: BT | O600: 308953.17 | P600: 6104672.3 | Q600: porta fusible tipo cabana fundido en sed 073 | R600: =IF(ISNUMBER(MATCH(J600, Causas!B:B, 0)), "Taxonomía Nueva", IF(ISNUMBER(MATCH(J600, 'Causas 1'!B:B, 0)), "Taxonomía Antigua", "HUÉRFANO")) -> Taxonomía Nueva | S600: =YEAR(G600) -> 2019 | T600: =IF(OR(ISBLANK(O599), O599=0, O599="", ISBLANK(P599), P599=0, P599=""), 1, 0) -> 0
B601: 201901150 | C601: 2 | D601: 0 | E601: 0 | F601: 14 | G601: 43711.793 | H601: 43711.88 | I601: 2.08 | J601: 26 | K601: I | L601: 7308 | M601: Teno | N601: BT | O601: 314897.02 | P601: 6138960.8 | Q601: se 397 operada en bt por cable en cosi por incendio de leña se repara quedando sector con energia | R601: =IF(ISNUMBER(MATCH(J601, Causas!B:B, 0)), "Taxonomía Nueva", IF(ISNUMBER(MATCH(J601, 'Causas 1'!B:B, 0)), "Taxonomía Antigua", "HUÉRFANO")) -> Taxonomía Nueva | S601: =YEAR(G601) -> 2019 | T601: =IF(OR(ISBLANK(O600), O600=0, O600="", ISBLANK(P600), P600=0, P600=""), 1, 0) -> 0
B602: 201901153 | C602: 9 | D602: 2 | E602: 575 | F602: 50 | G602: 43712.652 | H602: 43712.733 | I602: 1.94 | J602: 3 | K602: FM | L602: 7308 | M602: Teno | N602: MT | O602: 307466.61 | P602: 6142383.4 | Q602: dte3462 operan protecciones mt 20t, producto de líneas cortadas en te 6721 y 6722 , x quema de pastizales no autorizada 3ros , se repara y se normaliza quedando servicio normal en el sector | R602: =IF(ISNUMBER(MATCH(J602, Causas!B:B, 0)), "Taxonomía Nueva", IF(ISNUMBER(MATCH(J602, 'Causas 1'!B:B, 0)), "Taxonomía Antigua", "HUÉRFANO")) -> Taxonomía Nueva | S602: =YEAR(G602) -> 2019 | T602: =IF(OR(ISBLANK(O601), O601=0, O601="", ISBLANK(P601), P601=0, P601=""), 1, 0) -> 0
B603: 201901153 | C603: 9 | D603: 4 | E603: 170 | F603: 53 | G603: 43712.652 | H603: 43712.818 | I603: 3.98 | J603: 3 | K603: FM | L603: 7308 | M603: Teno | N603: MT | O603: 307466.61 | P603: 6142383.4 | Q603: dte3462 operan protecciones mt 20t, producto de líneas cortadas en te 6721 y 6722 , x quema de pastizales no autorizada 3ros , se repara y se normaliza quedando servicio normal en el sector | R603: =IF(ISNUMBER(MATCH(J603, Causas!B:B, 0)), "Taxonomía Nueva", IF(ISNUMBER(MATCH(J603, 'Causas 1'!B:B, 0)), "Taxonomía Antigua", "HUÉRFANO")) -> Taxonomía Nueva | S603: =YEAR(G603) -> 2019 | T603: =IF(OR(ISBLANK(O602), O602=0, O602="", ISBLANK(P602), P602=0, P602=""), 1, 0) -> 0
B604: 201901158 | C604: 9 | D604: 0 | E604: 0 | F604: 13 | G604: 43713.774 | H604: 43713.85 | I604: 1.8 | J604: 30 | K604: I | L604: 7308 | M604: Teno | N604: BT | O604: 306868.28 | P604: 6139338.6 | Q604: sector sin energía se506 operada en mt por alumbrado en cosi provocado por incendio,este se deja afuera quedando sector con energia | R604: =IF(ISNUMBER(MATCH(J604, Causas!B:B, 0)), "Taxonomía Nueva", IF(ISNUMBER(MATCH(J604, 'Causas 1'!B:B, 0)), "Taxonomía Antigua", "HUÉRFANO")) -> Taxonomía Nueva | S604: =YEAR(G604) -> 2019 | T604: =IF(OR(ISBLANK(O603), O603=0, O603="", ISBLANK(P603), P603=0, P603=""), 1, 0) -> 0
B605: 201901171 | C605: 6 | D605: 271 | E605: 22137.5 | F605: 3444 | G605: 43714.649 | H605: 43714.685 | I605: 0.85 | J605: 20 | K605: FM | L605: 7301 | M605: Curicó | N605: MT | O605: 296508.33 | P605: 6125585.8 | Q605: Choque de Vehiculo a tirante provoca daida de cuchilla solida | R605: =IF(ISNUMBER(MATCH(J605, Causas!B:B, 0)), "Taxonomía Nueva", IF(ISNUMBER(MATCH(J605, 'Causas 1'!B:B, 0)), "Taxonomía Antigua", "HUÉRFANO")) -> Taxonomía Nueva | S605: =YEAR(G605) -> 2019 | T605: =IF(OR(ISBLANK(O604), O604=0, O604="", ISBLANK(P604), P604=0, P604=""), 1, 0) -> 0
B606: 201901197 | C606: 7 | D606: 0 | E606: 0 | F606: 3 | G606: 43718.722 | H606: 43718.801 | I606: 1.89 | J606: 26 | K606: I | L606: 7301 | M606: Curicó | N606: BT | O606: 304259.1 | P606: 6113439.6 | Q606: sed 60 operada en bt fase 2y3 fusible de 40 a hyh opera por coci en cuenta 81 asociada a falla anterior | R606: =IF(ISNUMBER(MATCH(J606, Causas!B:B, 0)), "Taxonomía Nueva", IF(ISNUMBER(MATCH(J606, 'Causas 1'!B:B, 0)), "Taxonomía Antigua", "HUÉRFANO")) -> Taxonomía Nueva | S606: =YEAR(G606) -> 2019 | T606: =IF(OR(ISBLANK(O605), O605=0, O605="", ISBLANK(P605), P605=0, P605=""), 1, 0) -> 0
B607: 201901201 | C607: 9 | D607: 5 | E607: 250 | F607: 70 | G607: 43718.921 | H607: 43718.943 | I607: 0.52 | J607: 30 | K607: I | L607: 7308 | M607: Teno | N607: MT | O607: 309335.52 | P607: 6139238.4 | Q607: se encuentra prensa cortada en base puente de red mt cortado en dte 227 | R607: =IF(ISNUMBER(MATCH(J607, Causas!B:B, 0)), "Taxonomía Nueva", IF(ISNUMBER(MATCH(J607, 'Causas 1'!B:B, 0)), "Taxonomía Antigua", "HUÉRFANO")) -> Taxonomía Nueva | S607: =YEAR(G607) -> 2019 | T607: =IF(OR(ISBLANK(O606), O606=0, O606="", ISBLANK(P606), P606=0, P606=""), 1, 0) -> 0
B608: 201901201 | C608: 9 | D608: 13 | E608: 665 | F608: 199 | G608: 43718.921 | H608: 43718.945 | I608: 0.56 | J608: 30 | K608: I | L608: 7308 | M608: Teno | N608: MT | O608: 309335.52 | P608: 6139238.4 | Q608: se encuentra prensa cortada en base puente de red mt cortado en dte 227 | R608: =IF(ISNUMBER(MATCH(J608, Causas!B:B, 0)), "Taxonomía Nueva", IF(ISNUMBER(MATCH(J608, 'Causas 1'!B:B, 0)), "Taxonomía Antigua", "HUÉRFANO")) -> Taxonomía Nueva | S608: =YEAR(G608) -> 2019 | T608: =IF(OR(ISBLANK(O607), O607=0, O607="", ISBLANK(P607), P607=0, P607=""), 1, 0) -> 0
B609: 201901211 | C609: 2 | D609: 3 | E609: 25 | F609: 42 | G609: 43722.399 | H609: 43722.448 | I609: 1.16 | J609: 5 | K609: I | L609: 6303 | M609: Chimbarongo | N609: MT | O609: 311786.19 | P609: 6147372 | Q609: dte 4152 opera 2 fus mt 10t , x falla en el dte 4674 caída de gancho de álamo a la red , red sin daño se normaliza quedando servicio normal | R609: =IF(ISNUMBER(MATCH(J609, Causas!B:B, 0)), "Taxonomía Nueva", IF(ISNUMBER(MATCH(J609, 'Causas 1'!B:B, 0)), "Taxonomía Antigua", "HUÉRFANO")) -> Taxonomía Nueva | S609: =YEAR(G609) -> 2019 | T609: =IF(OR(ISBLANK(O608), O608=0, O608="", ISBLANK(P608), P608=0, P608=""), 1, 0) -> 0
B610: 201901211 | C610: 2 | D610: 2 | E610: 115 | F610: 4 | G610: 43722.399 | H610: 43722.477 | I610: 1.86 | J610: 5 | K610: I | L610: 6303 | M610: Chimbarongo | N610: MT | O610: 311244.28 | P610: 6146498.8 | Q610: dte 4152 opera 2 fus mt 10t , x falla en el dte 4674 caída de gancho de álamo a la red , red sin daño se normaliza quedando servicio normal | R610: =IF(ISNUMBER(MATCH(J610, Causas!B:B, 0)), "Taxonomía Nueva", IF(ISNUMBER(MATCH(J610, 'Causas 1'!B:B, 0)), "Taxonomía Antigua", "HUÉRFANO")) -> Taxonomía Nueva | S610: =YEAR(G610) -> 2019 | T610: =IF(OR(ISBLANK(O609), O609=0, O609="", ISBLANK(P609), P609=0, P609=""), 1, 0) -> 0
... B779: 202000748 | C779: 6 | D779: 0 | E779: 0 | F779: 21 | G779: 43993.898 | H779: 43994.145 | I779: 5.92 | J779: 2 | K779: I | L779: 7301 | M779: Curicó | N779: BT | O779: 303544.44 | P779: 6123303.6 | Q779: zapallar - fusible bt operador por ramas de aucalitus en SED | R779: =IF(ISNUMBER(MATCH(J779, Causas!B:B, 0)), "Taxonomía Nueva", IF(ISNUMBER(MATCH(J779, 'Causas 1'!B:B, 0)), "Taxonomía Antigua", "HUÉRFANO")) -> Taxonomía Nueva | S779: =YEAR(G779) -> 2020 | T779: =IF(OR(ISBLANK(O778), O778=0, O778="", ISBLANK(P778), P778=0, P778=""), 1, 0) -> 0
B780: 202000751 | C780: 6 | D780: 31 | E780: 1245 | F780: 431 | G780: 43994.334 | H780: 43994.466 | I780: 3.17 | J780: 5 | K780: I | L780: 7301 | M780: Curicó | N780: MT | O780: 2966733,75 | P780: 6119694,800 | Q780: El Maiten- Fusibles quemado dejando sector sin energia por caida de ramas en LMT | R780: =IF(ISNUMBER(MATCH(J780, Causas!B:B, 0)), "Taxonomía Nueva", IF(ISNUMBER(MATCH(J780, 'Causas 1'!B:B, 0)), "Taxonomía Antigua", "HUÉRFANO")) -> Taxonomía Nueva | S780: =YEAR(G780) -> 2020 | T780: =IF(OR(ISBLANK(O779), O779=0, O779="", ISBLANK(P779), P779=0, P779=""), 1, 0) -> 0
B781: 202000759 | C781: 9 | D781: 2 | E781: 15 | F781: 12 | G781: 43994.379 | H781: 43994.477 | I781: 2.34 | J781: 5 | K781: I | L781: 7308 | M781: Teno | N781: MT | O781: 318953.66 | P781: 6130818.1 | Q781: La Laguna - Caida de rama sobre linea de media tension proboca operacion de equipo | R781: =IF(ISNUMBER(MATCH(J781, Causas!B:B, 0)), "Taxonomía Nueva", IF(ISNUMBER(MATCH(J781, 'Causas 1'!B:B, 0)), "Taxonomía Antigua", "HUÉRFANO")) -> Taxonomía Nueva | S781: =YEAR(G781) -> 2020 | T781: =IF(OR(ISBLANK(O780), O780=0, O780="", ISBLANK(P780), P780=0, P780=""), 1, 0) -> 0
B782: 202000761 | C782: 7 | D782: 1 | E782: 75 | F782: 66 | G782: 43994.385 | H782: 43994.54 | I782: 3.72 | J782: 5 | K782: I | L782: 7301 | M782: Curicó | N782: MT | O782: 303635.81 | P782: 6110640.7 | Q782: Cordillerilla - Ramas rozando lineas de media tension. | R782: =IF(ISNUMBER(MATCH(J782, Causas!B:B, 0)), "Taxonomía Nueva", IF(ISNUMBER(MATCH(J782, 'Causas 1'!B:B, 0)), "Taxonomía Antigua", "HUÉRFANO")) -> Taxonomía Nueva | S782: =YEAR(G782) -> 2020 | T782: =IF(OR(ISBLANK(O781), O781=0, O781="", ISBLANK(P781), P781=0, P781=""), 1, 0) -> 0
B783: 202000762 | C783: 7 | D783: 1 | E783: 10 | F783: 2 | G783: 43994.402 | H783: 43994.687 | I783: 6.84 | J783: 2 | K783: I | L783: 7301 | M783: Curicó | N783: MT | O783: 314667.82 | P783: 6111544.2 | Q783: Upeo- fuete viento provoca caida de ramas y opera nh de S/E | R783: =IF(ISNUMBER(MATCH(J783, Causas!B:B, 0)), "Taxonomía Nueva", IF(ISNUMBER(MATCH(J783, 'Causas 1'!B:B, 0)), "Taxonomía Antigua", "HUÉRFANO")) -> Taxonomía Nueva | S783: =YEAR(G783) -> 2020 | T783: =IF(OR(ISBLANK(O782), O782=0, O782="", ISBLANK(P782), P782=0, P782=""), 1, 0) -> 0
B784: 202000762 | C784: 7 | D784: 1 | E784: 25 | F784: 17 | G784: 43994.405 | H784: 43994.638 | I784: 5.59 | J784: 2 | K784: I | L784: 7301 | M784: Curicó | N784: MT | O784: 312797.96 | P784: 6108227.6 | Q784: Upeo- fuete viento provoca caida de ramas y opera nh de S/E | R784: =IF(ISNUMBER(MATCH(J784, Causas!B:B, 0)), "Taxonomía Nueva", IF(ISNUMBER(MATCH(J784, 'Causas 1'!B:B, 0)), "Taxonomía Antigua", "HUÉRFANO")) -> Taxonomía Nueva | S784: =YEAR(G784) -> 2020 | T784: =IF(OR(ISBLANK(O783), O783=0, O783="", ISBLANK(P783), P783=0, P783=""), 1, 0) -> 0
B785: 202000762 | C785: 7 | D785: 10 | E785: 95 | F785: 59 | G785: 43994.534 | H785: 43994.54 | I785: 0.16 | J785: 2 | K785: I | L785: 7301 | M785: Curicó | N785: MT | O785: 315641.94 | P785: 6112466.3 | Q785: Upeo- fuete viento provoca caida de ramas y opera nh de S/E | R785: =IF(ISNUMBER(MATCH(J785, Causas!B:B, 0)), "Taxonomía Nueva", IF(ISNUMBER(MATCH(J785, 'Causas 1'!B:B, 0)), "Taxonomía Antigua", "HUÉRFANO")) -> Taxonomía Nueva | S785: =YEAR(G785) -> 2020 | T785: =IF(OR(ISBLANK(O784), O784=0, O784="", ISBLANK(P784), P784=0, P784=""), 1, 0) -> 0
B786: 202000764 | C786: 7 | D786: 2 | E786: 30 | F786: 17 | G786: 43994.421 | H786: 43994.643 | I786: 5.34 | J786: 5 | K786: I | L786: 7301 | M786: Curicó | N786: MT | O786: 311053.25 | P786: 6114314.3 | Q786: Los niches - ramas sobre linea de media tension. | R786: =IF(ISNUMBER(MATCH(J786, Causas!B:B, 0)), "Taxonomía Nueva", IF(ISNUMBER(MATCH(J786, 'Causas 1'!B:B, 0)), "Taxonomía Antigua", "HUÉRFANO")) -> Taxonomía Nueva | S786: =YEAR(G786) -> 2020 | T786: =IF(OR(ISBLANK(O785), O785=0, O785="", ISBLANK(P785), P785=0, P785=""), 1, 0) -> 0
B787: 202000768 | C787: 6 | D787: 4 | E787: 450 | F787: 6 | G787: 43994.456 | H787: 43994.6 | I787: 3.45 | J787: 4 | K787: I | L787: 7301 | M787: Curicó | N787: MT | O787: 300676.5 | P787: 6120602 | Q787: Los Niches - Lineas de media tension cortadas por caida de arbol. | R787: =IF(ISNUMBER(MATCH(J787, Causas!B:B, 0)), "Taxonomía Nueva", IF(ISNUMBER(MATCH(J787, 'Causas 1'!B:B, 0)), "Taxonomía Antigua", "HUÉRFANO")) -> Taxonomía Nueva | S787: =YEAR(G787) -> 2020 | T787: =IF(OR(ISBLANK(O786), O786=0, O786="", ISBLANK(P786), P786=0, P786=""), 1, 0) -> 0
B788: 202000793 | C788: 7 | D788: 0 | E788: 0 | F788: 211 | G788: 43996.334 | H788: 43996.427 | I788: 2.23 | J788: 5 | K788: I | L788: 7301 | M788: Curicó | N788: BT | O788: 303488.18 | P788: 6117056.4 | Q788: Los Niches - Fusible NH operado por línea BT cortada en neutro, se repara y se normaliza SE quedando con energía. | R788: =IF(ISNUMBER(MATCH(J788, Causas!B:B, 0)), "Taxonomía Nueva", IF(ISNUMBER(MATCH(J788, 'Causas 1'!B:B, 0)), "Taxonomía Antigua", "HUÉRFANO")) -> Taxonomía Nueva | S788: =YEAR(G788) -> 2020 | T788: =IF(OR(ISBLANK(O787), O787=0, O787="", ISBLANK(P787), P787=0, P787=""), 1, 0) -> 0
B789: 202000801 | C789: 9 | D789: 25 | E789: 641 | F789: 395 | G789: 43996.75 | H789: 43996.785 | I789: 0.83 | J789: 33 | K789: E | L789: 7306 | M789: Romeral | N789: MT | O789: 320325.24 | P789: 6129429.9 | Q789: Reconectador La Laguna, Operacion de reconectador de linea producto de aislador pasado en serviico particular en cta6866 fundo el barco | R789: =IF(ISNUMBER(MATCH(J789, Causas!B:B, 0)), "Taxonomía Nueva", IF(ISNUMBER(MATCH(J789, 'Causas 1'!B:B, 0)), "Taxonomía Antigua", "HUÉRFANO")) -> Taxonomía Nueva | S789: =YEAR(G789) -> 2020 | T789: =IF(OR(ISBLANK(O788), O788=0, O788="", ISBLANK(P788), P788=0, P788=""), 1, 0) -> 0
B790: 202000801 | C790: 9 | D790: 26 | E790: 661.5 | F790: 183 | G790: 43996.75 | H790: 43996.785 | I790: 0.83 | J790: 33 | K790: E | L790: 7308 | M790: Teno | N790: MT | O790: 320325.24 | P790: 6129429.9 | Q790: Reconectador La Laguna, Operacion de reconectador de linea producto de aislador pasado en serviico particular en cta6866 fundo el barco | R790: =IF(ISNUMBER(MATCH(J790, Causas!B:B, 0)), "Taxonomía Nueva", IF(ISNUMBER(MATCH(J790, 'Causas 1'!B:B, 0)), "Taxonomía Antigua", "HUÉRFANO")) -> Taxonomía Nueva | S790: =YEAR(G790) -> 2020 | T790: =IF(OR(ISBLANK(O789), O789=0, O789="", ISBLANK(P789), P789=0, P789=""), 1, 0) -> 0
...

Sheet Fallas del sistema
C3: Cantidad de fallas | F3: Horas con fallas
B4: Alimentador | C4: Externas | D4: Internas | E4: FM | F4: Horas (externas) | G4: Horas ( internas) | H4: Horas (FM)
B5: 2 | C5: 57 | D5: 246 | E5: 62 | F5: 24.2 | G5: 651.944 | H5: 261.63 | J5: =SUM(C5:E5) -> 365
B6: 6 | C6: 20 | D6: 429 | E6: 79 | F6: 4.21 | G6: 778.43611 | H6: 1310.351 | J6: =SUM(C6:E6) -> 528
B7: 7 | C7: 30 | D7: 399 | E7: 97 | F7: 17.956 | G7: 916 | H7: 2199.049 | J7: =SUM(C7:E7) -> 526
B8: 8 | C8: 25 | D8: 112 | E8: 42 | F8: 8.07 | G8: 177.693 | H8: 111.76 | J8: =SUM(C8:E8) -> 179
B9: 9 | C9: 46 | D9: 292 | E9: 78 | F9: 120.7 | G9: 708.49 | H9: 319.79 | J9: =SUM(C9:E9) -> 416
B10: 10 | C10: 7 | D10: 130 | E10: 25 | F10: 3.2 | G10: 291.95 | H10: 83.03 | J10: =SUM(C10:E10) -> 162
B11: 11 | C11: 1 | D11: 32 | E11: 13 | F11: 0.55 | G11: 23.66 | H11: 101 | J11: =SUM(C11:E11) -> 46
B12: Total por tipo | C12: =SUM(C5:C11) -> 186 | D12: =SUM(D5:D11) -> 1640 | E12: =SUM(E5:E11) -> 396 | F12: =SUM(F5:F11) -> 178.886 | G12: =SUM(G5:G11) -> 3548.1731 | H12: =SUM(H5:H11) -> 4386.61
B13: total | C13: =SUM(C12:E12) -> 2222 | F13: =SUM(F12:H12) -> 8113.6691

Sheet Diccionario_Taxonomia
A2: ID_Original | B2: Descripcion_Original | C2: Familia_Objetivo_CEC

Sheet DIAGNOSTICO
A4: Porcentaje de uso "Origen no determinado" (Cód 31)
A5: =COUNTIF(BD!J:J, 31) / (COUNTA(BD!B:B) - 1) -> 0.0099009901
A6: =COUNTIF(BD!J:J, 31) / (COUNTA(BD!A:A) - 1) -> -22

Sheet Causas
B2: Causa SEC | C2: Causa_comprimida | D2: Causa
B3: 1 | C3: Daño infraestructura evento catastrófico | D3: Daño en la infraestructura por eventos catastroficos de la naturaleza
B4: 2 | C4: Cortocircuito por evento catastrófico | D4: Cortocircuito producido por eventos externos catastroficos de la naturaleza
B5: 3 | C5: Incendio | D5: Incendio
B6: 4 | C6: Caída de árbol | D6: Caida de árbol
B7: 5 | C7: Impacto ganchos, ramas u otro tipo de vegetación | D7: Impacto de ganchos, ramas u otro tipo de vegetación
B8: 6 | C8: Impacto deslizamiento tierra, aluvión o socavón | D8: Impacto de elementos por un deslizamiento de tierra, aluvión o socavón
B9: 7 | C9: Impacto elementos maremoto o un tsunami | D9: Impacto de elementos por maremoto o un tsunami
B10: 8 | C10: Poda o tala árboles o roce de la vegetación | D10: Poda o tala de árboles o roce de la vegetación
B11: 9 | C11: Impacto de objeto | D11: Impacto de objeto
B12: 10 | C12: Contacto de objeto | D12: Contacto de objeto
B13: 11 | C13: Acción de animales | D13: Acción de animales
B14: 12 | C14: Acción de agua o de objetos arrastrados | D14: Acción de agua o de objetos arrastrados
... B38: 36 | C38: Desc. Prog. por mejora de CDS (excede tiempo) | D38: Desconexiones programadas por Obras en la red que permitan mejorar los estándares de calidad de suministro o producto, que excede el tiempo presupuestado

Sheet Causas 1
B2: Causa ID | C2: Clasificación | D2: Descripción | E2: Calificación
B3: 1001 | C3: Externas | D3: Racionamiento, con decreto vigente y programa de cortes avisado | E3: FM
B4: 1002 | C4: Externas | D4: Blackout del Sistema | E4: E
B5: 1003 | C5: Externas | D5: Programadas Generación | E5: E
B6: 1004 | C6: Externas | D6: Programadas Transmisión | E6: E
B7: 1005 | C7: Externas | D7: Programadas Subtransmisión | E7: E
B8: 1006 | C8: Externas | D8: Operación de bloque de baja frecuencia | E8: E
B9: 1007 | C9: Externas | D9: Otros | E9: E
B10: 1008 | C10: Externas | D10: Operación errónea de interruptor / relé / protecciones (Gx/Tx) | E10: E
B11: 1009 | C11: Externas | D11: Falla en sistema de control (Gx) | E11: E
B12: 1010 | C12: Externas | D12: Baja frecuencia (Gx/Tx) | E12: E
B13: 1011 | C13: Externas | D13: Sobre frecuencia (Gx/Tx) | E13: E
B14: 1012 | C14: Externas | D14: Interrupción forzada por operación de protecciones(Gx/Tx) | E14: E
... B142: 2702 | C142: Otros no clasificados | D142: Causas Fugaces o Flicker | E142: I

Sheet sist. Morza
B2: Sistema de distribucion MORZA
B3: INC | C3: Alimentador | D3: Trafos afectados | E3: KVA | F3: Clientes | G3: Inicio | H3: Fin | I3: Duracion | J3: Causa | K3: Calificación | L3: Comuna id | M3: Comuna | N3: Tension | O3: X | P3: Y | Q3: Descripcion
B4: 201901321 | C4: 2 | D4: 25 | E4: 1045 | F4: 183 | G4: 43747.1 | H4: 43747.144 | I4: 1.05 | J4: 32 | K4: E | L4: 6303 | M4: Chimbarongo | N4: MT | O4: 310796.98 | P4: 6147576.3 | Q4: Corte de conductor por intento de robo en 2 fases laterales entre estructuras 88 y 89 en tramo San Fernando - Chimbarongo se procede a realizar tranferencia de carga desde alimentador 52c9 S/E TENO energizando por MEdia tension
B5: 201901321 | C5: 2 | D5: 172 | E5: 16903 | F5: 1351 | G5: 43747.1 | H5: 43747.144 | I5: 1.05 | J5: 32 | K5: E | L5: 7308 | M5: Teno | N5: MT | O5: 310796.98 | P5: 6147576.3 | Q5: Corte de conductor por intento de robo en 2 fases laterales entre estructuras 88 y 89 en tramo San Fernando - Chimbarongo se procede a realizar tranferencia de carga desde alimentador 52c9 S/E TENO energizando por MEdia tension | AG5: tipos | AH5: cantidad de fallas | AI5: duracion total de fallas
B6: 202000069 | C6: 2 | D6: 26 | E6: 1090 | F6: 183 | G6: 43849.238 | H6: 43849.316 | I6: 1.87 | J6: 32 | K6: E | L6: 6303 | M6: Chimbarongo | N6: MT | O6: 310795.99 | P6: 6147614.2 | Q6: OPERACION LINEA TRANSMISION CGE AGUAS ARRIBA DE S/E QUINTA | AG6: externas | AH6: =COUNTA(K4:K60) -> 57 | AI6: =SUM(I4:I60) -> 24.2
B7: 202000069 | C7: 2 | D7: 184 | E7: 20578 | F7: 1457 | G7: 43849.238 | H7: 43849.316 | I7: 1.87 | J7: 32 | K7: E | L7: 7308 | M7: Teno | N7: MT | O7: 310795.99 | P7: 6147614.2 | Q7: OPERACION LINEA TRANSMISION CGE AGUAS ARRIBA DE S/E QUINTA | AG7: internas | AH7: =COUNTA(K123:K368) -> 246 | AI7: =SUM(I123:I368) -> 651.94444
B8: 202101405 | C8: 2 | D8: 30 | E8: 4845 | F8: 200 | G8: 44442.375 | H8: 44442.398 | I8: 0.55 | J8: 32 | K8: E | L8: 6303 | M8: Chimbarongo | N8: MT | O8: 310795.99 | P8: 6147614.2 | Q8: Sin Tensión en SE Quinta por falla a nivel de transmisión. | AG8: FM | AH8: =COUNTA(K61:K122) -> 62 | AI8: =SUM(I61:I122) -> 261.63333
B9: 202101405 | C9: 2 | D9: 187 | E9: 19033 | F9: 1438 | G9: 44442.375 | H9: 44442.398 | I9: 0.55 | J9: 32 | K9: E | L9: 7308 | M9: Teno | N9: MT | O9: 310795.99 | P9: 6147614.2 | Q9: Sin Tensión en SE Quinta por falla a nivel de transmisión.
B10: 202101609 | C10: 2 | D10: 30 | E10: 4845 | F10: 200 | G10: 44481.79 | H10: 44481.824 | I10: 0.82 | J10: 32 | K10: E | L10: 6303 | M10: Chimbarongo | N10: MT | O10: 310795.99 | P10: 6147614.2 | Q10: SE Quinta, Interrupción se produjo debido a un Ave se posa en la estructura de la barra de 66kva del patio de la S/E quinta , provocando una descarga a tierra, realizado operación de los 3 Fusible de alta tensión AT 80E del patio de S/E Quinta
B11: 202101609 | C11: 2 | D11: 187 | E11: 19033 | F11: 1438 | G11: 44481.79 | H11: 44481.824 | I11: 0.82 | J11: 32 | K11: E | L11: 7308 | M11: Teno | N11: MT | O11: 310795.99 | P11: 6147614.2 | Q11: SE Quinta, Interrupción se produjo debido a un Ave se posa en la estructura de la barra de 66kva del patio de la S/E quinta , provocando una descarga a tierra, realizado operación de los 3 Fusible de alta tensión AT 80E del patio de S/E Quinta
B12: 202200221 | C12: 2 | D12: 30 | E12: 4845 | F12: 202 | G12: 44605.593 | H12: 44605.597 | I12: 0.1 | J12: 32 | K12: E | L12: 6303 | M12: Chimbarongo | N12: MT | O12: 310795.99 | P12: 6147614.2 | Q12: SSEE Quinta Perdida de suministro a nivel de 154kV subestación Tinguiririca que alimenta sector de san fernando - TRANSELEC.
B13: 202200221 | C13: 2 | D13: 188 | E13: 19078 | F13: 1439 | G13: 44605.593 | H13: 44605.597 | I13: 0.1 | J13: 32 | K13: E | L13: 7308 | M13: Teno | N13: MT | O13: 310795.99 | P13: 6147614.2 | Q13: SSEE Quinta Perdida de suministro a nivel de 154kV subestación Tinguiririca que alimenta sector de san fernando - TRANSELEC.
B14: 202200262 | C14: 2 | D14: 30 | E14: 4845 | F14: 202 | G14: 44614.55 | H14: 44614.557 | I14: 0.17 | J14: 32 | K14: E | L14: 6303 | M14: Chimbarongo | N14: MT | O14: 310795.99 | P14: 6147614.2 | Q14: Ramón Urrea de SSEE Y Protecciones (CGE) quien informó que a las 13:12 hrs opero el 52B8 en SE San Fernando, por lo tanto queremos alimentamos por la barra de 66KV desde subestación Teno a las 13:22 hrs.
B15: 202200262 | C15: 2 | D15: 188 | E15: 19078 | F15: 1439 | G15: 44614.55 | H15: 44614.557 | I15: 0.17 | J15: 32 | K15: E | L15: 7308 | M15: Teno | N15: MT | O15: 310795.99 | P15: 6147614.2 | Q15: Ramón Urrea de SSEE Y Protecciones (CGE) quien informó que a las 13:12 hrs opero el 52B8 en SE San Fernando, por lo tanto queremos alimentamos por la barra de 66KV desde subestación Teno a las 13:22 hrs.
B16: 202300432 | C16: 2 | D16: 3 | E16: 105 | F16: 10 | G16: 45020.727 | H16: 45020.732 | I16: 0.1 | J16: 32 | K16: E | L16: 6303 | M16: Chimbarongo | N16: MT | Q16: SS/EE Quinta - Opera reconectador de cabecera 52C1 Morza por EDAC.
B17: 202300432 | C17: 2 | D17: 117 | E17: 14468 | F17: 903 | G17: 45020.727 | H17: 45020.732 | I17: 0.1 | J17: 32 | K17: E | L17: 7308 | M17: Teno | N17: MT | Q17: SS/EE Quinta - Opera reconectador de cabecera 52C1 Morza por EDAC.
B18: 202301830 | C18: 2 | D18: 31 | E18: 4940 | F18: 252 | G18: 45226.181 | H18: 45226.189 | I18: 0.2 | J18: 32 | K18: E | L18: 6303 | M18: Chimbarongo | N18: MT | Q18: Falla en la LT 66 KV San Fernando – Teno perdiendo 1.6 MW
B19: 202301830 | C19: 2 | D19: 199 | E19: 20015.5 | F19: 1559 | G19: 45226.181 | H19: 45226.189 | I19: 0.2 | J19: 32 | K19: E | L19: 7308 | M19: Teno | N19: MT | Q19: Falla en la LT 66 KV San Fernando – Teno perdiendo 1.6 MW
B20: 202301911 | C20: 2 | D20: 31 | E20: 4940 | F20: 253 | G20: 45234.793 | H20: 45234.8 | I20: 0.17 | J20: 32 | K20: E | L20: 6303 | M20: Chimbarongo | N20: MT | Q20: SSEE Quinta, se encuentra sin tensión por falla aguas arriba de nuestras instalaciones a nivel de transmisión, se transfieren consumos a SSEE Teno y posteriormente normalizados a SSEE Quinta.
B21: 202301911 | C21: 2 | D21: 199 | E21: 20015.5 | F21: 1562 | G21: 45234.793 | H21: 45234.8 | I21: 0.17 | J21: 32 | K21: E | L21: 7308 | M21: Teno | N21: MT | Q21: SSEE Quinta, se encuentra sin tensión por falla aguas arriba de nuestras instalaciones a nivel de transmisión, se transfieren consumos a SSEE Teno y posteriormente normalizados a SSEE Quinta.
B22: 202302070 | C22: 2 | D22: 31 | E22: 4940 | F22: 253 | G22: 45270.781 | H22: 45270.799 | I22: 0.42 | J22: 32 | K22: E | L22: 6303 | M22: Chimbarongo | N22: MT | Q22: SS/EE Quinta - Falla Aguas Arriba sistema de distribución, producto de una interrupción forzada por protecciones, se pierden 7.3 MW de consumos correspondientes a SS/EE Chimbarongo, Quinta, según IF2023004841.
B23: 202302070 | C23: 2 | D23: 199 | E23: 20015.5 | F23: 1563 | G23: 45270.781 | H23: 45270.799 | I23: 0.42 | J23: 32 | K23: E | L23: 7308 | M23: Teno | N23: MT | Q23: SS/EE Quinta - Falla Aguas Arriba sistema de distribución, producto de una interrupción forzada por protecciones, se pierden 7.3 MW de consumos correspondientes a SS/EE Chimbarongo, Quinta, según IF2023004841.
B24: 202400211 | C24: 2 | D24: 31 | E24: 4940 | F24: 258 | G24: 45331.856 | H24: 45331.864 | I24: 0.18 | J24: 32 | K24: E | L24: 6303 | M24: Chimbarongo | N24: MT | Q24: Falla Externa a Redes CEC - Falla Transelec Falla en transformador n°4 de línea 154kva SS/EE Itahue
B25: 202400211 | C25: 2 | D25: 199 | E25: 20035.5 | F25: 1580 | G25: 45331.856 | H25: 45331.864 | I25: 0.18 | J25: 32 | K25: E | L25: 7308 | M25: Teno | N25: MT | Q25: Falla Externa a Redes CEC - Falla Transelec Falla en transformador n°4 de línea 154kva SS/EE Itahue
B26: 202400338 | C26: 2 | D26: 3 | E26: 105 | F26: 10 | G26: 45353.406 | H26: 45353.417 | I26: 0.28 | J26: 32 | K26: E | L26: 6303 | M26: Chimbarongo | N26: MT | Q26: Opera reconectador de cabecera 52C1 por EDAC.
B27: 202400338 | C27: 2 | D27: 120 | E27: 15125.5 | F27: 931 | G27: 45353.406 | H27: 45353.417 | I27: 0.28 | J27: 32 | K27: E | L27: 7308 | M27: Teno | N27: MT | Q27: Opera reconectador de cabecera 52C1 por EDAC.
... B49: 202501326 | C49: 2 | D49: 209 | E49: 19612.5 | F49: 1676 | G49: 45949.037 | H49: 45949.05 | I49: 0.3 | J49: 32 | K49: E | L49: 7308 | M49: Teno | N49: MT | Q49: Sin Tensión en SSEE Quinta por: S/E San Fernando 52B8 de línea de 66 kV San Fernando - Teno interrupción forzada por protecciones – Afecta Alimentador 52C2 Morza asociado a SSEE Quinta.
B50: 201900577 | C50: 2 | D50: 1 | E50: 75 | F50: 45 | G50: 43598.308 | H50: 43598.38 | I50: 1.72 | J50: 33 | K50: E | L50: 7308 | M50: Teno | N50: MT | O50: 316711.23 | P50: 6143751.5 | Q50: dte 5818 operado en mt fase tys fus de 5st opera por cuenta 10845 operada en mt se repone dte 5818 y se deja cuenta abierta
B51: 201900577 | C51: 2 | D51: 1 | E51: 15 | F51: 1 | G51: 43598.37 | H51: 43598.38 | I51: 0.23 | J51: 33 | K51: E | L51: 7308 | M51: Teno | N51: MT | O51: 316965.29 | P51: 6144181.2 | Q51: dte 5818 operado en mt fase tys fus de 5st opera por cuenta 10845 operada en mt se repone dte 5818 y se deja cuenta abierta
B52: 202300538 | C52: 2 | D52: 31 | E52: 4940 | F52: 247 | G52: 45046.025 | H52: 45046.051 | I52: 0.62 | J52: 33 | K52: E | L52: 6303 | M52: Chimbarongo | N52: MT | Q52: S/E Quinta Falla externa en la línea de 66kV San Fernando - Chimbarongo (aguas arriba de nuestro sistema de distribución), y que afectó a clientes conectados al alimentador denominado 52C2 Morza en SE Quinta.
B53: 202300538 | C53: 2 | D53: 195 | E53: 19363 | F53: 1534 | G53: 45046.025 | H53: 45046.051 | I53: 0.62 | J53: 33 | K53: E | L53: 7308 | M53: Teno | N53: MT | Q53: S/E Quinta Falla externa en la línea de 66kV San Fernando - Chimbarongo (aguas arriba de nuestro sistema de distribución), y que afectó a clientes conectados al alimentador denominado 52C2 Morza en SE Quinta.
B54: 202300538 | C54: 2 | D54: 31 | E54: 4940 | F54: 247 | G54: 45046.399 | H54: 45046.4 | I54: 0.02 | J54: 33 | K54: E | L54: 6303 | M54: Chimbarongo | N54: MT | Q54: S/E Quinta Falla externa en la línea de 66kV San Fernando - Chimbarongo (aguas arriba de nuestro sistema de distribución), y que afectó a clientes conectados al alimentador denominado 52C2 Morza en SE Quinta.
B55: 202300538 | C55: 2 | D55: 195 | E55: 19363 | F55: 1534 | G55: 45046.399 | H55: 45046.4 | I55: 0.02 | J55: 33 | K55: E | L55: 7308 | M55: Teno | N55: MT | Q55: S/E Quinta Falla externa en la línea de 66kV San Fernando - Chimbarongo (aguas arriba de nuestro sistema de distribución), y que afectó a clientes conectados al alimentador denominado 52C2 Morza en SE Quinta.
B56: 202300578 | C56: 2 | D56: 24 | E56: 1105 | F56: 250 | G56: 45050.682 | H56: 45050.711 | I56: 0.69 | J56: 33 | K56: E | L56: 7308 | M56: Teno | N56: MT | Q56: Sector San Leon de Morza, operación de 1 fusible MT en fase central en DTE4056 producto del choque de un camión al poste PTE236 particular servicio 12519, el vehículo se encontraba al interior del lugar y realiza una maniobra mal y choca un poste de acometida en Media tensión provocando la operación de fusibles y al caer el poste por tensión mueve las líneas de la red Media tensión de distribución operando los fusibles asociados al sector, se realizan maniobras para aislar falla y normalización de fusibles de Media tensión con la misma capacidad 25T quedando normalizado el suministro eléctrico en la zona afectada
B57: 202300914 | C57: 2 | D57: 31 | E57: 4940 | F57: 250 | G57: 45100.988 | H57: 45100.992 | I57: 0.1 | J57: 33 | K57: E | L57: 6303 | M57: Chimbarongo | N57: MT | Q57: Sector Quinta - CGE presenta Falla en lines 154kv a las 23:42hrs entre san fernando y tingiririca a las 23:49 realizaron intento de cierre negativo.. aun mantiene la falla , realizaran tranferencia en Linea de 66kv. desde S/E Teno
B58: 202300914 | C58: 2 | D58: 196 | E58: 19848 | F58: 1538 | G58: 45100.988 | H58: 45100.992 | I58: 0.1 | J58: 33 | K58: E | L58: 7308 | M58: Teno | N58: MT | Q58: Sector Quinta - CGE presenta Falla en lines 154kv a las 23:42hrs entre san fernando y tingiririca a las 23:49 realizaron intento de cierre negativo.. aun mantiene la falla , realizaran tranferencia en Linea de 66kv. desde S/E Teno
B59: 202301144 | C59: 2 | D59: 31 | E59: 4940 | F59: 253 | G59: 45139.098 | H59: 45139.115 | I59: 0.4 | J59: 33 | K59: E | L59: 6303 | M59: Chimbarongo | N59: MT | Q59: Sector Quinta - CGE presenta Falla en lines 154kv a las 02:21hrs entre Línea de 154 kV Alto Jahuel Tinguiririca 1 interrupción forzada por protecciones, se pierden aproximadamente 150 MW, realizaran tranferencia en distribucion a las 02:45hrs. desde S/E Teno normalizando los consumos.
B60: 202301144 | C60: 2 | D60: 196 | E60: 19848 | F60: 1538 | G60: 45139.098 | H60: 45139.115 | I60: 0.4 | J60: 33 | K60: E | L60: 7308 | M60: Teno | N60: MT | Q60: Sector Quinta - CGE presenta Falla en lines 154kv a las 02:21hrs entre Línea de 154 kV Alto Jahuel Tinguiririca 1 interrupción forzada por protecciones, se pierden aproximadamente 150 MW, realizaran tranferencia en distribucion a las 02:45hrs. desde S/E Teno normalizando los consumos.
B61: 202401339 | C61: 2 | D61: 1 | E61: 75 | F61: 1 | G61: 45506.046 | H61: 45506.591 | I61: 13.1 | J61: 4 | K61: FM | L61: 6303 | M61: Chimbarongo | N61: MT | Q61: Sector Las Liras , sector sin energia poda caida de arboles cortando LMt y quebrando postes en varios tramos por viento fuerte
B62: 202401339 | C62: 2 | D62: 39 | E62: 2650 | F62: 385 | G62: 45506.046 | H62: 45506.591 | I62: 13.1 | J62: 4 | K62: FM | L62: 7308 | M62: Teno | N62: MT | Q62: Sector Las Liras , sector sin energia poda caida de arboles cortando LMt y quebrando postes en varios tramos por viento fuerte
...

Sheet Digsilent Morza
A1: carga | B1: u, p.u | C1: MW | D1: MVAr | E1: MVA | F1: FP | K1: Alimentador | L1: MW | M1: MVAr | N1: MVA | O1: U,p.u | P1: FP
A2: BCTE4145 | C2: -0, | D2: -0,97191228404 | E2: 0,97191228404 | F2: -0,
A3: BCTE4180 | C3: 0, | D3: -0,31835354736 | E3: 0,31835354736 | F3: 0,
A4: CL000962_unifrutti | C4: 0,36346370585 | D4: 0,052829025317 | E4: 0,36728295821 | F4: 0,98960133524
A5: CL001721_unifrutti | C5: 0,38251459078 | D5: 0,33271352951 | E5: 0,50696716351 | F5: 0,75451551563
A6: CL002960_gabriel_lozano | C6: 0,27775883234 | D6: 0,22329631309 | E6: 0,35638632462 | F6: 0,77937567506
A7: CL007361_project_fruit | C7: 0,002192714636 | D7: 0,003289071828 | E7: 0,003952972422 | F7: 0,55470021099
A8: CL008416_neptuno | C8: 0,19237010206 | D8: 0,003260510104 | E8: 0,19239773152 | F8: 0,99985639406
A9: S0000103 | C9: -0,000451084838 | D9: 0,006223431246 | E9: 0,006239757528 | F9: -0,072292045994
A10: S0000104 | C10: -0,000179425713 | D10: 0,002475604009 | E10: 0,002482097661 | F10: -0,072287934426
A11: S0000105 | C11: -0,000460960015 | D11: 0,006360040605 | E11: 0,006376723346 | F11: -0,072287911864
A12: S0000106 | C12: -0,000154719927 | D12: 0,002134729923 | E12: 0,002140329437 | F12: -0,072287903124
A13: S0000107 | C13: -0,000280613887 | D13: 0,00387173715 | E13: 0,003881892929 | F13: -0,072287899851
... A237: S0001495 | C237: -0,00003135388 | D237: 0,000432601438 | E237: 0,000433736175 | F237: -0,072287905664

Sheet sist. zapallar
B4: INC | C4: Alimentador | D4: Trafos afectados | E4: KVA | F4: Clientes | G4: Inicio | H4: Fin | I4: Duracion | J4: Causa | K4: Calificación | L4: Comuna id | M4: Comuna | N4: Tension | O4: X | P4: Y | Q4: Descripcion
B5: 201900458 | C5: 6 | D5: 269 | E5: 22107.5 | F5: 3378 | G5: 43565.013 | H5: 43565.021 | I5: 0.18 | J5: 32 | K5: E | L5: 7301 | M5: Curicó | N5: MT | O5: 296508.02 | P5: 6125591 | Q5: operacion falla edac, informada por sts osorno S/E 52c6 curico
B6: 201900580 | C6: 6 | D6: 253 | E6: 21609.5 | F6: 3333 | G6: 43598.658 | H6: 43598.671 | I6: 0.32 | J6: 32 | K6: E | L6: 7301 | M6: Curicó | N6: MT | O6: 296508.33 | P6: 6125585.8 | Q6: falla edac | AF6: tipo | AG6: cantidad de fallas | AH6: horas de fallas
B7: 202100153 | C7: 6 | D7: 291 | E7: 25037.5 | F7: 3715 | G7: 44227.136 | H7: 44227.171 | I7: 0.83 | J7: 32 | K7: E | L7: 7301 | M7: Curicó | N7: MT | O7: 296508.33 | P7: 6125585.8 | Q7: Interrupción Línea Itahue - Teno por tormenta eléctrica | AF7: interna | AG7: =COUNTA(K104:K532) -> 429 | AH7: =SUM(I104:I532) -> 778.43611
B8: 202100153 | C8: 6 | D8: 256 | E8: 16946.5 | F8: 2624 | G8: 44227.136 | H8: 44227.171 | I8: 0.83 | J8: 32 | K8: E | L8: 7301 | M8: Curicó | N8: MT | O8: 296508.33 | P8: 6125585.8 | Q8: Interrupción Línea Itahue - Teno por tormenta eléctrica | AF8: externa | AG8: =COUNTA(K5:K24) -> 20 | AH8: =SUM(I5:I24) -> 4.21
B9: 202100153 | C9: 6 | D9: 62 | E9: 3656 | F9: 493 | G9: 44227.136 | H9: 44227.138 | I9: 0.05 | J9: 32 | K9: E | L9: 7301 | M9: Curicó | N9: MT | O9: 296508.33 | P9: 6125585.8 | Q9: Interrupción Línea Itahue - Teno por tormenta eléctrica | AF9: FM | AG9: =COUNTA(K25:K103) -> 79 | AH9: =SUM(I25:I103) -> 1310.3508
B10: 202100153 | C10: 6 | D10: 34 | E10: 2144.5 | F10: 276 | G10: 44227.136 | H10: 44227.171 | I10: 0.83 | J10: 32 | K10: E | L10: 7304 | M10: Molina | N10: MT | O10: 296508.33 | P10: 6125585.8 | Q10: Interrupción Línea Itahue - Teno por tormenta eléctrica
B11: 202100153 | C11: 6 | D11: 18 | E11: 9297 | F11: 62 | G11: 44227.136 | H11: 44227.138 | I11: 0.05 | J11: 32 | K11: E | L11: 7306 | M11: Romeral | N11: MT | O11: 296508.33 | P11: 6125585.8 | Q11: Interrupción Línea Itahue - Teno por tormenta eléctrica
B12: 202100153 | C12: 6 | D12: 27 | E12: 666 | F12: 396 | G12: 44227.136 | H12: 44227.138 | I12: 0.05 | J12: 32 | K12: E | L12: 7306 | M12: Romeral | N12: MT | O12: 296508.33 | P12: 6125585.8 | Q12: Interrupción Línea Itahue - Teno por tormenta eléctrica
B13: 202100153 | C13: 6 | D13: 160 | E13: 18381 | F13: 1721 | G13: 44227.136 | H13: 44227.138 | I13: 0.05 | J13: 32 | K13: E | L13: 7308 | M13: Teno | N13: MT | O13: 296508.33 | P13: 6125585.8 | Q13: Interrupción Línea Itahue - Teno por tormenta eléctrica
B14: 202100153 | C14: 6 | D14: 124 | E14: 15466.5 | F14: 1113 | G14: 44227.136 | H14: 44227.138 | I14: 0.05 | J14: 32 | K14: E | L14: 7308 | M14: Teno | N14: MT | O14: 296508.33 | P14: 6125585.8 | Q14: Interrupción Línea Itahue - Teno por tormenta eléctrica
B15: 202200364 | C15: 6 | D15: 208 | E15: 20938.5 | F15: 2797 | G15: 44631.66 | H15: 44631.662 | I15: 0.07 | J15: 32 | K15: E | L15: 7301 | M15: Curicó | N15: MT | O15: 296508.33 | P15: 6125585.8 | Q15: Falla Asociada a Subtransmisión SS/EE Curicó Y SS/EE Teno, sin energía por periodo de 5 minutos.
B16: 202201993 | C16: 6 | D16: 304 | E16: 26032.5 | F16: 4133 | G16: 44916.189 | H16: 44916.191 | I16: 0.06 | J16: 32 | K16: E | L16: 7301 | M16: Curicó | N16: MT | O16: 296508.33 | P16: 6125585.8 | Q16: Falla Asociada a nivel de transmisión aguas arriba SSEE Curicó Y SSEE Teno, por falla en línea 154kv Itahue - Tinguiririca de Transelec.
B17: 202300088 | C17: 6 | D17: 309 | E17: 26555 | F17: 4157 | G17: 44944.789 | H17: 44944.792 | I17: 0.08 | J17: 32 | K17: E | L17: 7301 | M17: Curicó | N17: MT | Q17: Falla Asociada a nivel de transmisión aguas arriba SSEE Curicó Y SSEE Teno, por falla en línea 154kv Itahue - Tinguiririca.
B18: 202300175 | C18: 6 | D18: 216 | E18: 21421.5 | F18: 2978 | G18: 44957.687 | H18: 44957.699 | I18: 0.28 | J18: 32 | K18: E | L18: 7301 | M18: Curicó | N18: MT | Q18: 52C6 La Obra - Zapallar, apertura de alimentador producto de falla Edac.
B19: 202500199 | C19: 6 | D19: 95 | E19: 5487.5 | F19: 1287 | G19: 45703.633 | H19: 45703.637 | I19: 0.08 | J19: 32 | K19: E | L19: 7301 | M19: Curicó | N19: MT | Q19: SSEE Curicó, se produce la ausencia de tensión de la S/E Curicó de provocando la suspensión del suministro de energía eléctrica causada Perdida de suministro por una falla por Operación automática del Cto N°2 Itahue – Tinguiririca de Transelec.
B20: 202500199 | C20: 6 | D20: 225 | E20: 22620.5 | F20: 3148 | G20: 45703.633 | H20: 45703.637 | I20: 0.08 | J20: 32 | K20: E | L20: 7301 | M20: Curicó | N20: MT | Q20: SSEE Curicó, se produce la ausencia de tensión de la S/E Curicó de provocando la suspensión del suministro de energía eléctrica causada Perdida de suministro por una falla por Operación automática del Cto N°2 Itahue – Tinguiririca de Transelec.
B21: 202500199 | C21: 6 | D21: 300 | E21: 20263 | F21: 3350 | G21: 45703.633 | H21: 45703.637 | I21: 0.08 | J21: 32 | K21: E | L21: 7301 | M21: Curicó | N21: MT | Q21: SSEE Curicó, se produce la ausencia de tensión de la S/E Curicó de provocando la suspensión del suministro de energía eléctrica causada Perdida de suministro por una falla por Operación automática del Cto N°2 Itahue – Tinguiririca de Transelec.
B22: 202500199 | C22: 6 | D22: 77 | E22: 4727.5 | F22: 606 | G22: 45703.633 | H22: 45703.637 | I22: 0.08 | J22: 32 | K22: E | L22: 7301 | M22: Curicó | N22: MT | Q22: SSEE Curicó, se produce la ausencia de tensión de la S/E Curicó de provocando la suspensión del suministro de energía eléctrica causada Perdida de suministro por una falla por Operación automática del Cto N°2 Itahue – Tinguiririca de Transelec.
B23: 202500199 | C23: 6 | D23: 37 | E23: 2224.5 | F23: 329 | G23: 45703.633 | H23: 45703.637 | I23: 0.08 | J23: 32 | K23: E | L23: 7304 | M23: Molina | N23: MT | Q23: SSEE Curicó, se produce la ausencia de tensión de la S/E Curicó de provocando la suspensión del suministro de energía eléctrica causada Perdida de suministro por una falla por Operación automática del Cto N°2 Itahue – Tinguiririca de Transelec.
B24: 202500199 | C24: 6 | D24: 19 | E24: 9607 | F24: 73 | G24: 45703.633 | H24: 45703.637 | I24: 0.08 | J24: 32 | K24: E | L24: 7306 | M24: Romeral | N24: MT | Q24: SSEE Curicó, se produce la ausencia de tensión de la S/E Curicó de provocando la suspensión del suministro de energía eléctrica causada Perdida de suministro por una falla por Operación automática del Cto N°2 Itahue – Tinguiririca de Transelec.
B25: 201800011 | C25: 6 | D25: 1 | E25: 25 | F25: 47 | G25: 43121.89 | H25: 43121.938 | I25: 1.1333333 | J25: 1701 | K25: FM | L25: 7301 | M25: Curicó | N25: MT | O25: 298723.92 | P25: 6115497.1 | Q25: Se abre DCU3293
B26: 201800019 | C26: 6 | D26: 1 | E26: 25 | F26: 4 | G26: 43139.556 | H26: 43139.729 | I26: 4.1666667 | J26: 1601 | K26: FM | L26: 7301 | M26: Curicó | N26: MT | O26: 297876.39 | P26: 6123087.7 | Q26: Se abre DCU1925
B27: 201800022 | C27: 6 | D27: 17 | E27: 495 | F27: 51 | G27: 43142.931 | H27: 43143.149 | I27: 5.2333333 | J27: 1601 | K27: FM | L27: 7301 | M27: Curicó | N27: MT | O27: 300176.96 | P27: 6121266.8 | Q27: Se abre DCU3326
B28: 201800030 | C28: 6 | D28: 1 | E28: 112 | F28: 91 | G28: 43146.759 | H28: 43146.844 | I28: 2.0333333 | J28: 1602 | K28: FM | L28: 7301 | M28: Curicó | N28: MT | O28: 298254.51 | P28: 6125753.6 | Q28: Se abre DCU5047
B29: 201800158 | C29: 6 | D29: 258 | E29: 21420 | F29: 3298 | G29: 43219.299 | H29: 43219.445 | I29: 3.5166667 | J29: 1601 | K29: FM | L29: 7301 | M29: Curicó | N29: MT | O29: 296559.35 | P29: 6125623.6 | Q29: Se abre RCU5388
B30: 201800181 | C30: 6 | D30: 258 | E30: 21420 | F30: 3298 | G30: 43235.684 | H30: 43235.711 | I30: 0.64083333 | J30: 1602 | K30: FM | L30: 7301 | M30: Curicó | N30: MT | O30: 296559.35 | P30: 6125623.6 | Q30: Se abre RCU5388
B31: 201800351 | C31: 6 | D31: 1 | E31: 15 | F31: 26 | G31: 43332.8 | H31: 43332.85 | I31: 1.1966667 | J31: 1701 | K31: FM | L31: 7301 | M31: Curicó | N31: MT | O31: 297443.29 | P31: 6121562 | Q31: Se abre FMT440
B32: 201900705 | C32: 6 | D32: 1 | E32: 25 | F32: 49 | G32: 43616.759 | H32: 43616.811 | I32: 1.26 | J32: 13 | K32: FM | L32: 7301 | M32: Curicó | N32: MT | O32: 298783.58 | P32: 6115597.2 | Q32: 1 fusible MT 2 T operado en CU 4667 a causa caida de rayo quemando equipo de medicion de voltaje UDAT quedando sin comunicacion
B33: 201900705 | C33: 6 | D33: 2 | E33: 40 | F33: 44 | G33: 43616.765 | H33: 43616.828 | I33: 1.51 | J33: 13 | K33: FM | L33: 7301 | M33: Curicó | N33: MT | O33: 298754.98 | P33: 6115628.5 | Q33: 1 fusible MT 2 T operado en CU 4667 a causa caida de rayo quemando equipo de medicion de voltaje UDAT quedando sin comunicacion
B34: 201900705 | C34: 6 | D34: 1 | E34: 15 | F34: 3 | G34: 43616.807 | H34: 43616.896 | I34: 2.12 | J34: 13 | K34: FM | L34: 7301 | M34: Curicó | N34: MT | O34: 298811.51 | P34: 6117605.5 | Q34: 1 fusible MT 2 T operado en CU 4667 a causa caida de rayo quemando equipo de medicion de voltaje UDAT quedando sin comunicacion
B35: 201900804 | C35: 6 | D35: 1 | E35: 45 | F35: 16 | G35: 43627.779 | H35: 43628.237 | I35: 10.99 | J35: 20 | K35: FM | L35: 7301 | M35: Curicó | N35: MT | O35: 297647.23 | P35: 6122278.7 | Q35: RECONECTADOR LA OBRA OPERADO POR CHOQUE DE VEHICULO PATENTE WC8018 A POSTE PLACA CU8197.
B36: 201900804 | C36: 6 | D36: 45 | E36: 2120 | F36: 475 | G36: 43627.838 | H36: 43627.901 | I36: 1.51 | J36: 20 | K36: FM | L36: 7301 | M36: Curicó | N36: MT | O36: 297753.24 | P36: 6122599.1 | Q36: RECONECTADOR LA OBRA OPERADO POR CHOQUE DE VEHICULO PATENTE WC8018 A POSTE PLACA CU8197.
... B68: 202200229 | C68: 6 | D68: 22 | E68: 915 | F68: 245 | G68: 44607.988 | H68: 44608.03 | I68: 1 | J68: 20 | K68: FM | L68: 7301 | M68: Curicó | N68: MT | O68: 297753.24 | P68: 6122599.1 | Q68: Sector Santa Cristina La Obra - Operacion de reconectador RCU5724 Producto de el choque de un vehiculo al poste CU-1606, realizando la reparacion con contratista SOELEC.
B69: 202300202 | C69: 6 | D69: 71 | E69: 5959.5 | F69: 1330 | G69: 44961.697 | H69: 44961.718 | I69: 0.49 | J69: 20 | K69: FM | L69: 7301 | M69: Curicó | N69: MT | Q69: Sector Camino Los niches RCU5455 operación de reconectador producto de choque de poste CU3428 por un camión marca Scania de nacionalidad brasileño, se realiza cambio de poste con personal contratista quedando sector normalizado
B70: 202300202 | C70: 6 | D70: 16 | E70: 515 | F70: 84 | G70: 44961.697 | H70: 44961.719 | I70: 0.53 | J70: 20 | K70: FM | L70: 7301 | M70: Curicó | N70: MT | Q70: Sector Camino Los niches RCU5455 operación de reconectador producto de choque de poste CU3428 por un camión marca Scania de nacionalidad brasileño, se realiza cambio de poste con personal contratista quedando sector normalizado
B71: 202300202 | C71: 6 | D71: 28 | E71: 1567 | F71: 90 | G71: 44961.697 | H71: 44961.968 | I71: 6.5 | J71: 20 | K71: FM | L71: 7301 | M71: Curicó | N71: MT | Q71: Sector Camino Los niches RCU5455 operación de reconectador producto de choque de poste CU3428 por un camión marca Scania de nacionalidad brasileño, se realiza cambio de poste con personal contratista quedando sector normalizado
B72: 202301065 | C72: 6 | D72: 54 | E72: 2168 | F72: 457 | G72: 45129.208 | H72: 45129.259 | I72: 1.22 | J72: 20 | K72: FM | L72: 7301 | M72: Curicó | N72: MT | Q72: Sector Los cristales DCU7433 opera en media tensión por choque de vehículo a poste CU6078, se realiza reparación de la falla quedando con servicio normal
B73: 202301065 | C73: 6 | D73: 15 | E73: 588 | F73: 95 | G73: 45129.208 | H73: 45129.346 | I73: 3.29 | J73: 20 | K73: FM | L73: 7301 | M73: Curicó | N73: MT | Q73: Sector Los cristales DCU7433 opera en media tensión por choque de vehículo a poste CU6078, se realiza reparación de la falla quedando con servicio normal
B74: 202301361 | C74: 6 | D74: 7 | E74: 974.5 | F74: 61 | G74: 45160.015 | H74: 45162.566 | I74: 61.22 | J74: 12 | K74: FM | L74: 7301 | M74: Curicó | N74: MT | Q74: Sector Parque de Zapallar, DCU5047. Se realiza apertura de emergencia de desconectadores fusibles por inundaciones en el sector, el cual estaba socavando caminos y por ende la postación, provocando arrastre de la postacion, LMT y LBT.
...

Sheet Digsilent Zapallar
A1: carga | B1: u, p.u | C1: MW | D1: MVAr | E1: MVA | F1: FP | K1: Alimentador | L1: MW | M1: MVAr | N1: MVA | O1: U,p.u | P1: FP
A2: BCTE1479 | B2: 0,98347538952 | C2: 0, | D2: -0,14016135121 | E2: 0,14016135121 | F2: 0, | K2: 52C10mv | L2: 5.6432048 | M2: 2.3548421 | N2: 6.1148214 | O2: 1.011 | P2: 0.92287319
A3: BCTE3779 | B3: 0,98729790123 | C3: 0, | D3: -0,28504664747 | E3: 0,28504664747 | F3: 0, | H3: Clientes | I3: 207
A4: CL002267_copefrut | B4: 0,98233609686 | C4: 14304526141 | D4: 0,26907674796 | E4: 14555400982 | F4: 0,98276414086 | H4: MVA | I4: =SUM(E2:E208) -> 14555400982
A5: CL011327_copefrut | B5: 0,98217948762 | C5: 0,61726222239 | D5: 0,17741669408 | E5: 0,64225332582 | F5: 0,96108840169
A6: CL015335_lcm | B6: 0,98357551864 | C6: 0,84395944084 | D6: 0,22957927152 | E6: 0,87462802362 | F6: 0,96493528455
A7: CL015702_agrocol | B7: 0,99136021209 | C7: 0,63260714782 | D7: 0,20093451342 | E7: 0,66375182271 | F7: 0,95307783146
A8: CL015703_sm_service | B8: 0,99077615969 | C8: 0,56449748671 | D8: 0,28419528823 | E8: 0,63200029616 | F8: 0,89319180724
A9: S0000127 | B9: 0,98199471711 | C9: 0,019974720442 | D9: 0,009377245683 | E9: 0,022066313542 | F9: 0,90521329735
A10: S0000128 | B10: 0,98474140353
A11: S0000129 | B11: 0,99666474161 | C11: 0,012760577895 | D11: 0,005990525491 | E11: 0,014096763596 | F11: 0,90521330008
A12: S0000131 | B12: 0,99793511767
A13: S0000139 | B13: 0,98655791085
A14: S0000140 | B14: 0,98626853195 | C14: 0,013650549371 | D14: 0,006408327566 | E14: 0,01507992574 | F14: 0,90521330187
A15: S0000144 | B15: 0,98817519092 | C15: 0,012452539857 | D15: 0,005845915116 | E15: 0,013756470202 | F15: 0,90521330499
A16: S0000146 | B16: 0,98840000996 | C16: 0,020758087666 | D16: 0,009745000957 | E16: 0,022931708336 | F16: 0,90521331259
A17: S0000147 | B17: 10180554608
A18: S0000148 | B18: 0,9867111094
A19: S0000149 | B19: 0,98581238357 | C19: 0,009544696088 | D19: 0,004480811584 | E19: 0,010544140357 | F19: 0,90521330001
A20: S0000151 | B20: 0,
